<?xml version="1.0"?>
<robot xmlns:xacro="http://www.ros.org/wiki/xacro" name="slambot">

  <!-- Simulation flavor: true = Gazebo Sim (Ignition) via gz_ros2_control, false = Gazebo Classic -->
  <xacro:arg name="use_gz" default="true"/>
  <!-- If true in Gazebo Sim, move base kinematically from /cmd_vel (disables wheel physics effect) -->
  <xacro:arg name="kinematic" default="true"/>

 
  <!-- Base link with simple box visual and collision -->
  <link name="base_link">
    <inertial>
      <!-- Raise base so its bottom touches wheel top (0.097 m) -->
      <origin xyz="0 0 0.05" rpy="0 0 0"/>
      <mass value="2.0"/>
      <inertia ixx="0.011483" ixy="0.0" ixz="0.0" iyy="0.021483" iyz="0.0" izz="0.030833"/>
    </inertial>
    <visual>
      <origin xyz="0 0 0.05" rpy="0 0 0"/>
      <geometry>
        <box size="0.297 0.256 0.08"/>
      </geometry>
      <material name="gray">
        <color rgba="0.6 0.6 0.6 1.0"/>
      </material>
    </visual>
    <collision>
      <origin xyz="0 0 0.05" rpy="0 0 0"/>
      <geometry>
        <box size="0.297 0.256 0.08"/>
      </geometry>
    </collision>
  </link>

  <!-- IMU -->
  <link name="imu_link">
    <inertial>
      <origin xyz="0 0 0.1" rpy="0 0 0"/>
      <mass value="0.02"/>
      <inertia ixx="3.333e-06" ixy="0.0" ixz="0.0" iyy="3.333e-06" iyz="0.0" izz="5.333e-06"/>
    </inertial>
    <visual>
      <origin xyz="0 0 0.1" rpy="0 0 0"/>
      <geometry>
        <box size="0.04 0.04 0.02"/>
      </geometry>
      <material name="blue">
        <color rgba="0.2 0.4 0.9 1.0"/>
      </material>
    </visual>
    <collision>
      <origin xyz="0 0 0.1" rpy="0 0 0"/>
      <geometry>
        <box size="0.04 0.04 0.02"/>
      </geometry>
    </collision>
  </link>
  <joint name="imu_mount" type="fixed">
    <parent link="base_link"/>
    <child link="imu_link"/>
    <origin xyz="0 0 0" rpy="0 0 3.1415926535"/>
  </joint>

  <!-- LiDAR -->
  <link name="laser_link">
    <inertial>
      <origin xyz="0 0 -0.137" rpy="0 0 0"/>
      <mass value="0.1"/>
      <inertia ixx="4.396e-05" ixy="0.0" ixz="0.0" iyy="4.396e-05" iyz="0.0" izz="6.125e-05"/>
    </inertial>
    <visual>
      <origin xyz="0 0 -0.137" rpy="0 0 0"/>
      <geometry>
        <cylinder radius="0.035" length="0.04"/>
      </geometry>
      <material name="black">
        <color rgba="0.1 0.1 0.1 1.0"/>
      </material>
    </visual>
    <collision>
      <origin xyz="0 0 -0.137" rpy="0 0 0"/>
      <geometry>
        <cylinder radius="0.035" length="0.04"/>
      </geometry>
    </collision>
  </link>
  <joint name="laser_mount" type="fixed">
    <parent link="base_link"/>
    <child link="laser_link"/>
    <origin xyz="0.10 0 0.247" rpy="0 0 0"/>
  </joint>

  <!-- Wheel parameters: radius=0.05m, width=0.02m
       Track width (y): +/-0.15m, Wheelbase (x): +/-0.15m
       Wheel cylinders are rotated so axis aligns with joint axis (y). -->

  <link name="front_left_wheel">
    <inertial>
      <origin xyz="0 0 0" rpy="1.5708 0 0"/>
      <mass value="0.2"/>
      <inertia ixx="0.0001317" ixy="0.0" ixz="0.0" iyy="0.00025" iyz="0.0" izz="0.0001317"/>
    </inertial>
    <visual>
      <origin xyz="0 0 0" rpy="1.5708 0 0"/>
      <geometry>
        <cylinder radius="0.0485" length="0.048"/>
      </geometry>
      <material name="wheel_black">
        <color rgba="0.05 0.05 0.05 1.0"/>
      </material>
    </visual>
    <collision>
      <origin xyz="0 0 0" rpy="1.5708 0 0"/>
      <geometry>
        <cylinder radius="0.0485" length="0.048"/>
      </geometry>
    </collision>
  </link>
  <joint name="front_left_wheel_joint" type="continuous">
    <parent link="base_link"/>
    <child link="front_left_wheel"/>
    <origin xyz="0.1485 0.152 0.0485" rpy="0 0 0"/>
    <axis xyz="0 1 0"/>
  </joint>

  <link name="front_right_wheel">
    <inertial>
      <origin xyz="0 0 0" rpy="1.5708 0 0"/>
      <mass value="0.2"/>
      <inertia ixx="0.0001317" ixy="0.0" ixz="0.0" iyy="0.00025" iyz="0.0" izz="0.0001317"/>
    </inertial>
    <visual>
      <origin xyz="0 0 0" rpy="1.5708 0 0"/>
      <geometry>
        <cylinder radius="0.0485" length="0.048"/>
      </geometry>
      <material name="wheel_black"/>
    </visual>
    <collision>
      <origin xyz="0 0 0" rpy="1.5708 0 0"/>
      <geometry>
        <cylinder radius="0.0485" length="0.048"/>
      </geometry>
    </collision>
  </link>
  <joint name="front_right_wheel_joint" type="continuous">
    <parent link="base_link"/>
    <child link="front_right_wheel"/>
    <origin xyz="0.1485 -0.152 0.0485" rpy="0 0 0"/>
    <axis xyz="0 1 0"/>
  </joint>

  <link name="back_left_wheel">
    <inertial>
      <origin xyz="0 0 0" rpy="1.5708 0 0"/>
      <mass value="0.2"/>
      <inertia ixx="0.0001317" ixy="0.0" ixz="0.0" iyy="0.00025" iyz="0.0" izz="0.0001317"/>
    </inertial>
    <visual>
      <origin xyz="0 0 0" rpy="1.5708 0 0"/>
      <geometry>
        <cylinder radius="0.0485" length="0.048"/>
      </geometry>
      <material name="wheel_black"/>
    </visual>
    <collision>
      <origin xyz="0 0 0" rpy="1.5708 0 0"/>
      <geometry>
        <cylinder radius="0.0485" length="0.048"/>
      </geometry>
    </collision>
  </link>
  <joint name="back_left_wheel_joint" type="continuous">
    <parent link="base_link"/>
    <child link="back_left_wheel"/>
    <origin xyz="-0.1485 0.152 0.0485" rpy="0 0 0"/>
    <axis xyz="0 1 0"/>
  </joint>

  <link name="back_right_wheel">
    <inertial>
      <origin xyz="0 0 0" rpy="1.5708 0 0"/>
      <mass value="0.2"/>
      <inertia ixx="0.0001317" ixy="0.0" ixz="0.0" iyy="0.00025" iyz="0.0" izz="0.0001317"/>
    </inertial>
    <visual>
      <origin xyz="0 0 0" rpy="1.5708 0 0"/>
      <geometry>
        <cylinder radius="0.0485" length="0.048"/>
      </geometry>
      <material name="wheel_black"/>
    </visual>
    <collision>
      <origin xyz="0 0 0" rpy="1.5708 0 0"/>
      <geometry>
        <cylinder radius="0.0485" length="0.048"/>
      </geometry>
    </collision>
  </link>
  <joint name="back_right_wheel_joint" type="continuous">
    <parent link="base_link"/>
    <child link="back_right_wheel"/>
    <origin xyz="-0.1485 -0.152 0.0485" rpy="0 0 0"/>
    <axis xyz="0 1 0"/>
  </joint>

  <transmission name="front_left_transmission">
    <type>transmission_interface/SimpleTransmission</type>
    <joint name="front_left_wheel_joint">
      <hardwareInterface>hardware_interface/VelocityCommandInterface</hardwareInterface>
    </joint>
    <actuator name="front_left_motor">
      <hardwareInterface>hardware_interface/VelocityCommandInterface</hardwareInterface>
      <mechanicalReduction>1</mechanicalReduction>
    </actuator>
  </transmission>

  <transmission name="front_right_transmission">
    <type>transmission_interface/SimpleTransmission</type>
    <joint name="front_right_wheel_joint">
      <hardwareInterface>hardware_interface/VelocityCommandInterface</hardwareInterface>
    </joint>
    <actuator name="front_right_motor">
      <hardwareInterface>hardware_interface/VelocityCommandInterface</hardwareInterface>
      <mechanicalReduction>1</mechanicalReduction>
    </actuator>
  </transmission>

  <transmission name="back_left_transmission">
    <type>transmission_interface/SimpleTransmission</type>
    <joint name="back_left_wheel_joint">
      <hardwareInterface>hardware_interface/VelocityCommandInterface</hardwareInterface>
    </joint>
    <actuator name="back_left_motor">
      <hardwareInterface>hardware_interface/VelocityCommandInterface</hardwareInterface>
      <mechanicalReduction>1</mechanicalReduction>
    </actuator>
  </transmission>

  <transmission name="back_right_transmission">
    <type>transmission_interface/SimpleTransmission</type>
    <joint name="back_right_wheel_joint">
      <hardwareInterface>hardware_interface/VelocityCommandInterface</hardwareInterface>
    </joint>
    <actuator name="back_right_motor">
      <hardwareInterface>hardware_interface/VelocityCommandInterface</hardwareInterface>
      <mechanicalReduction>1</mechanicalReduction>
    </actuator>
  </transmission>

  <!-- ros2_control interfaces; hardware plugin varies by sim flavor -->
  <ros2_control name="slambot_system" type="system">
    <xacro:if value="$(arg use_gz)">
      <hardware>
        <plugin>gz_ros2_control/GazeboSimSystem</plugin>
      </hardware>
    </xacro:if>
    <xacro:unless value="$(arg use_gz)">
      <hardware>
        <plugin>gazebo_ros2_control/GazeboSystem</plugin>
      </hardware>
    </xacro:unless>

    <joint name="front_left_wheel_joint">
      <command_interface name="velocity"/>
      <state_interface name="position"/>
      <state_interface name="velocity"/>
    </joint>

    <joint name="front_right_wheel_joint">
      <command_interface name="velocity"/>
      <state_interface name="position"/>
      <state_interface name="velocity"/>
    </joint>

    <joint name="back_left_wheel_joint">
      <command_interface name="velocity"/>
      <state_interface name="position"/>
      <state_interface name="velocity"/>
    </joint>

    <joint name="back_right_wheel_joint">
      <command_interface name="velocity"/>
      <state_interface name="position"/>
      <state_interface name="velocity"/>
    </joint>
  </ros2_control>

  <xacro:if value="$(arg use_gz)">
    <gazebo>
      <plugin
          name="gz_ros2_control::GazeboSimROS2ControlPlugin"
          filename="libgz_ros2_control-system.so">

        <ros2_control>
          slambot_system
        </ros2_control>

        <!-- Path to controller manager parameters YAML -->
        <parameters>$(find slambot_description)/config/mecanum_controller.yaml</parameters>

      </plugin>

      <!-- Kinematic base controller: apply /cmd_vel directly to model velocity (Gazebo Sim) -->
      <xacro:if value="$(arg kinematic)">
        <plugin name="slambot_kinematic_base" filename="libslambot_kinematic_base.so">
          <topic>/cmd_vel</topic>
          <max_linear>1.5</max_linear>
          <max_angular>3.0</max_angular>
        </plugin>
      </xacro:if>
    </gazebo>
  </xacro:if>

  <xacro:unless value="$(arg use_gz)">
    <gazebo>
      <plugin name="gazebo_ros2_control" filename="libgazebo_ros2_control.so">
        <!-- Path to controller manager parameters YAML -->
        <parameters>$(find slambot_description)/config/mecanum_controller.yaml</parameters>
      </plugin>
    </gazebo>
  </xacro:unless>

  <!-- Approximate mecanum behavior via anisotropic friction directions (Gazebo Classic ODE only) -->
  <xacro:unless value="$(arg use_gz)">
    <gazebo reference="front_left_wheel">
      <mu1>1.0</mu1>
      <mu2>0.05</mu2>
      <fdir1>1 1 0</fdir1>
    </gazebo>
    <gazebo reference="front_right_wheel">
      <mu1>1.0</mu1>
      <mu2>0.05</mu2>
      <fdir1>1 -1 0</fdir1>
    </gazebo>
    <gazebo reference="back_left_wheel">
      <mu1>1.0</mu1>
      <mu2>0.05</mu2>
      <fdir1>-1 -1 0</fdir1>
    </gazebo>
    <gazebo reference="back_right_wheel">
      <mu1>1.0</mu1>
      <mu2>0.05</mu2>
      <fdir1>-1 1 0</fdir1>
    </gazebo>
  </xacro:unless>


</robot>
